<?xml version="1.0" ?>
<!-- =================================================================================== -->
<!-- |    This document was autogenerated by xacro from rover.urdf.xacro               | -->
<!-- |    EDITING THIS FILE BY HAND IS NOT RECOMMENDED                                 | -->
<!-- =================================================================================== -->
<robot name="wave_rover">
  <gazebo reference="base_link">
    <mu1>0.2</mu1>
    <mu2>0.2</mu2>
    <material>Gazebo/Black</material>
  </gazebo>
  <gazebo reference="bracket_stand_link">
    <material>Gazebo/Black</material>
  </gazebo>
  <gazebo reference="camera_bracket_link">
    <material>Gazebo/Black</material>
  </gazebo>
  <gazebo reference="camera_link">
    <material>Gazebo/Silver</material>
  </gazebo>
  <gazebo reference="front_left_wheel">
    <mu1>0.2</mu1>
    <mu2>0.2</mu2>
    <material>Gazebo/Black</material>
  </gazebo>
  <gazebo reference="front_right_wheel">
    <mu1>0.2</mu1>
    <mu2>0.2</mu2>
    <material>Gazebo/Black</material>
  </gazebo>
  <gazebo reference="back_left_wheel">
    <mu1>0.2</mu1>
    <mu2>0.2</mu2>
    <material>Gazebo/Black</material>
  </gazebo>
  <gazebo reference="back_right_wheel">
    <mu1>0.2</mu1>
    <mu2>0.2</mu2>
    <material>Gazebo/Black</material>
  </gazebo>
  <gazebo reference="camera_sensor_link">
    <sensor name="camera" type="depth">
      <update_rate>30.0</update_rate>
      <camera>
        <horizontal_fov>1.3962634</horizontal_fov>
        <image>
          <width>640</width>
          <height>480</height>
          <format>R8G8B8</format>
        </image>
        <clip>
          <near>0.1</near>
          <far>5.0</far>
        </clip>
      </camera>
      <plugin filename="libgazebo_ros_camera.so" name="camera_controller">
        <ros>
          <namespace>/camera</namespace>
        </ros>
        <camera_name>camera</camera_name>
        <image_topic_name>image_raw</image_topic_name>
        <depth_image_topic_name>depth/image_raw</depth_image_topic_name>
        <info_topic_name>camera_info</info_topic_name>
        <point_cloud_topic_name>depth/points</point_cloud_topic_name>
        <frame_name>camera_link_optical</frame_name>
      </plugin>
    </sensor>
  </gazebo>
  <!-- Diff Drive Plugin -->
  <gazebo>
    <plugin filename="libgazebo_ros_diff_drive.so" name="diff_drive_controller">
      <ros>
        <namespace>/wave_rover</namespace>
      </ros>
      <num_wheel_pairs>2</num_wheel_pairs>
      <left_joints>
        <left_joint>front_left_wheel_joint</left_joint>
        <left_joint>back_left_wheel_joint</left_joint>
      </left_joints>
      <right_joints>
        <right_joint>front_right_wheel_joint</right_joint>
        <right_joint>back_right_wheel_joint</right_joint>
      </right_joints>
      <wheel_separation>0.11730000000000002</wheel_separation>
      <wheel_diameter>0.08</wheel_diameter>
      <max_wheel_torque>5000</max_wheel_torque>
      <max_wheel_acceleration>7.0</max_wheel_acceleration>
      <!--<wheelAcceleration>1.0</wheelAcceleration>-->
      <command_topic>cmd_vel</command_topic>
      <odometry_topic>odom</odometry_topic>
      <odometrySource>1</odometrySource>
      <odometry_frame>odom</odometry_frame>
      <robot_base_frame>dummy</robot_base_frame>
      <publish_odom>true</publish_odom>
      <publish_odom_tf>true</publish_odom_tf>
      <publish_wheel_tf>false</publish_wheel_tf>
    </plugin>
  </gazebo>
  <!-- Prevent fixed joint lumping -->
  <gazebo>
    <preserveFixedJoint>true</preserveFixedJoint>
    <disableFixedJointLumping>true</disableFixedJointLumping>
  </gazebo>
  <!-- Ensure robot is dynamic -->
  <gazebo>
    <static>false</static>
  </gazebo>
  <!-- ######################################################################### -->
  <!-- From here Links and Joints are defined                                    -->
  <!-- ######################################################################### -->
  <link name="dummy">
 </link>
  <joint name="dummy_joint" type="fixed">
    <parent link="dummy"/>
    <child link="base_link"/>
  </joint>
  <!-- Base -->
  <link name="base_link">
    <visual>
      <origin rpy="0 0 0" xyz="0 0 0"/>
      <geometry>
        <mesh filename="package://wave_rover_description/meshes/wave_rover_model.stl" scale="0.001 0.001 0.001"/>
      </geometry>
      <material name="grey">
        <color rgba="0.6 0.6 0.6 1.0"/>
      </material>
    </visual>
    <collision>
      <geometry>
        <box size="0.1828 0.0753 0.0542"/>
      </geometry>
    </collision>
    <inertial>
      <mass value="2.02180722888"/>
      <inertia ixx="2.8063835398211366e-06" ixy="0.0" ixz="0.0" iyy="0.01" iyz="0.0" izz="3.192278949949509e-05"/>
    </inertial>
  </link>
  <!-- Bracket Stand -->
  <link name="bracket_stand_link">
    <visual>
      <geometry>
        <box size="0.045 0.11 0.04"/>
      </geometry>
      <material name="black">
        <color rgba="0.1 0.1 0.1 1.0"/>
      </material>
    </visual>
    <inertial>
      <mass value="0.1"/>
      <inertia ixx="1e-5" ixy="0.0" ixz="0.0" iyy="1e-5" iyz="0.0" izz="1e-5"/>
    </inertial>
  </link>
  <joint name="bracket_stand_mount" type="fixed">
    <parent link="base_link"/>
    <child link="bracket_stand_link"/>
    <origin rpy="0 0 0" xyz="0.0 0.0042 0.07"/>
  </joint>
  <!-- Camera Bracket -->
  <link name="camera_bracket_link">
    <visual>
      <geometry>
        <mesh filename="package://wave_rover_description/meshes/realsense_bracket.stl" scale="0.001 0.001 0.001"/>
      </geometry>
    </visual>
    <inertial>
      <mass value="0.05"/>
      <inertia ixx="1e-6" ixy="0.0" ixz="0.0" iyy="1e-6" iyz="0.0" izz="1e-6"/>
    </inertial>
  </link>
  <joint name="bracket_mount" type="fixed">
    <parent link="bracket_stand_link"/>
    <child link="camera_bracket_link"/>
    <origin rpy="0 0 0" xyz="0.0 -0.04 0.02"/>
  </joint>
  <!-- Camera -->
  <link name="camera_link">
    <visual>
      <geometry>
        <mesh filename="package://wave_rover_description/meshes/d435.stl" scale="0.01 0.01 0.01"/>
      </geometry>
      <material name="blue">
        <color rgba="0.1 0.1 1.0 1.0"/>
      </material>
    </visual>
    <inertial>
      <mass value="0.2"/>
      <inertia ixx="1e-4" ixy="0.0" ixz="0.0" iyy="1e-4" iyz="0.0" izz="1e-4"/>
    </inertial>
  </link>
  <joint name="camera_mount" type="fixed">
    <parent link="camera_bracket_link"/>
    <child link="camera_link"/>
    <origin rpy="0.349 0 0" xyz="0.0 -0.03 0.02"/>
  </joint>
  <!-- Sensor Link -->
  <link name="camera_sensor_link">
    <inertial>
      <mass value="0.001"/>
      <inertia ixx="1e-8" ixy="0.0" ixz="0.0" iyy="1e-8" iyz="0.0" izz="1e-8"/>
    </inertial>
  </link>
  <joint name="camera_sensor_joint" type="fixed">
    <parent link="camera_link"/>
    <child link="camera_sensor_link"/>
    <origin rpy="0 0 -1.5708" xyz="0 0 0"/>
  </joint>
  <!-- Optical Frame -->
  <link name="camera_link_optical">
    <inertial>
      <mass value="0.001"/>
      <inertia ixx="1e-8" ixy="0.0" ixz="0.0" iyy="1e-8" iyz="0.0" izz="1e-8"/>
    </inertial>
  </link>
  <joint name="camera_optical_joint" type="fixed">
    <parent link="camera_sensor_link"/>
    <child link="camera_link_optical"/>
    <origin rpy="-1.5708 0 -1.5708" xyz="0 0 0"/>
  </joint>
  <!-- Wheel Links -->
  <link name="front_left_wheel">
    <inertial>
      <origin rpy="0 0 0" xyz="0 0 0"/>
      <mass value="14.303043016920002"/>
      <inertia ixx="6.055336291643253e-05" ixy="0.0" ixz="0.0" iyy="6.055336291643253e-05" iyz="0" izz="0.0005046113576369377"/>
    </inertial>
    <collision name="front_left_collision">
      <origin rpy="1.5708 0 0" xyz="0 0 0"/>
      <geometry>
        <cylinder length="0.042" radius="0.04"/>
      </geometry>
    </collision>
    <visual name="front_left_visual">
      <origin rpy="1.570795 0 0" xyz="0 0 0"/>
      <geometry>
        <mesh filename="package://wave_rover_description/meshes/front_left_wheel.stl" scale="0.001 0.001 0.001"/>
      </geometry>
    </visual>
  </link>
  <link name="front_right_wheel">
    <inertial>
      <origin rpy="0 0 0" xyz="0 0 0"/>
      <mass value="14.303043016920002"/>
      <inertia ixx="6.055336291643253e-05" ixy="0.0" ixz="0.0" iyy="6.055336291643253e-05" iyz="0" izz="0.0005046113576369377"/>
    </inertial>
    <collision name="front_right_collision">
      <origin rpy="1.5708 0 0" xyz="0 0 0"/>
      <geometry>
        <cylinder length="0.042" radius="0.04"/>
      </geometry>
    </collision>
    <visual name="front_right_visual">
      <origin rpy="1.570795 0 0" xyz="0 0 0"/>
      <geometry>
        <mesh filename="package://wave_rover_description/meshes/front_right_wheel.stl" scale="0.001 0.001 0.001"/>
      </geometry>
    </visual>
  </link>
  <link name="back_left_wheel">
    <inertial>
      <origin rpy="0 0 0" xyz="0 0 0"/>
      <mass value="14.303043016920002"/>
      <inertia ixx="6.055336291643253e-05" ixy="0.0" ixz="0.0" iyy="6.055336291643253e-05" iyz="0" izz="0.0005046113576369377"/>
    </inertial>
    <collision name="back_left_collision">
      <origin rpy="1.5708 0 0" xyz="0 0 0"/>
      <geometry>
        <cylinder length="0.042" radius="0.04"/>
      </geometry>
    </collision>
    <visual name="back_left_visual">
      <origin rpy="1.570795 0 0" xyz="0 0 0"/>
      <geometry>
        <mesh filename="package://wave_rover_description/meshes/back_left_wheel.stl" scale="0.001 0.001 0.001"/>
      </geometry>
    </visual>
  </link>
  <link name="back_right_wheel">
    <inertial>
      <origin rpy="0 0 0" xyz="0 0 0"/>
      <mass value="14.303043016920002"/>
      <inertia ixx="6.055336291643253e-05" ixy="0.0" ixz="0.0" iyy="6.055336291643253e-05" iyz="0" izz="0.0005046113576369377"/>
    </inertial>
    <collision name="back_right_collision">
      <origin rpy="1.5708 0 0" xyz="0 0 0"/>
      <geometry>
        <cylinder length="0.042" radius="0.04"/>
      </geometry>
    </collision>
    <visual name="back_right_visual">
      <origin rpy="1.570795 0 0" xyz="0 0 0"/>
      <geometry>
        <mesh filename="package://wave_rover_description/meshes/back_right_wheel.stl" scale="0.001 0.001 0.001"/>
      </geometry>
    </visual>
  </link>
  <!-- Wheel Joints with Damping -->
  <joint name="front_left_wheel_joint" type="revolute">
    <parent link="base_link"/>
    <child link="front_left_wheel"/>
    <origin rpy="0 0 0" xyz="0 0 0"/>
    <axis>
      <xyz>0 1 0</xyz>
      <dynamics damping="1.0" friction="1.0"/>
    </axis>
    <limit effort="10.0" lower="-1000" upper="1000" velocity="10.0"/>
  </joint>
  <joint name="front_right_wheel_joint" type="revolute">
    <parent link="base_link"/>
    <child link="front_right_wheel"/>
    <origin rpy="0 0 0" xyz="0 0 0"/>
    <axis>
      <xyz>0 1 0</xyz>
      <dynamics damping="1.0" friction="1.0"/>
    </axis>
    <limit effort="10.0" lower="-1000" upper="1000" velocity="10.0"/>
  </joint>
  <joint name="back_left_wheel_joint" type="revolute">
    <parent link="base_link"/>
    <child link="back_left_wheel"/>
    <origin rpy="0 0 0" xyz="0 0 0"/>
    <axis>
      <xyz>0 1 0</xyz>
      <dynamics damping="1.0" friction="1.0"/>
    </axis>
    <limit effort="10.0" lower="-1000" upper="1000" velocity="10.0"/>
  </joint>
  <joint name="back_right_wheel_joint" type="revolute">
    <parent link="base_link"/>
    <child link="back_right_wheel"/>
    <origin rpy="0 0 0" xyz="0 0 0"/>
    <axis>
      <xyz>0 1 0</xyz>
      <dynamics damping="1.0" friction="1.0"/>
    </axis>
    <limit effort="10.0" lower="-1000" upper="1000" velocity="10.0"/>
  </joint>
</robot>
